Traceback (most recent call last):
  File "main.py", line 13, in <module>
    model = sys.argv[2]
IndexError: list index out of range
