[I 17:12:56.140 LabApp] Using EnvironmentKernelSpecManager...
[I 17:12:56.141 LabApp] Started periodic updates of the kernel list (every 3 minutes).
[I 17:12:56.587 LabApp] JupyterLab beta preview extension loaded from /home/ubuntu/anaconda3/lib/python3.6/site-packages/jupyterlab
[I 17:12:56.588 LabApp] JupyterLab application directory is /home/ubuntu/anaconda3/share/jupyter/lab
[I 17:12:56.766 LabApp] [nb_conda] enabled
/home/ubuntu/anaconda3/lib/python3.6/site-packages/matplotlib/__init__.py:1067: UserWarning: Duplicate key in file "/home/ubuntu/.config/matplotlib/matplotlibrc", line #2
  (fname, cnt))
/home/ubuntu/anaconda3/lib/python3.6/site-packages/matplotlib/__init__.py:1067: UserWarning: Duplicate key in file "/home/ubuntu/.config/matplotlib/matplotlibrc", line #3
  (fname, cnt))
[I 17:12:57.435 LabApp] sparkmagic extension enabled!
[I 17:12:57.438 LabApp] Serving notebooks from local directory: /data2/Code/zebrafish_passivity
[I 17:12:57.439 LabApp] 0 active kernels
[I 17:12:57.439 LabApp] The Jupyter Notebook is running at:
[I 17:12:57.439 LabApp] http://localhost:8002/?token=b8a49f28c93d8c72fc38fbf3ab776de3afc3de69d6cbc758
[I 17:12:57.439 LabApp] Use Control-C to stop this server and shut down all kernels (twice to skip confirmation).
[C 17:12:57.439 LabApp] 
    
    Copy/paste this URL into your browser when you connect for the first time,
    to login with a token:
        http://localhost:8002/?token=b8a49f28c93d8c72fc38fbf3ab776de3afc3de69d6cbc758&token=b8a49f28c93d8c72fc38fbf3ab776de3afc3de69d6cbc758
[I 17:12:57.439 LabApp] Starting initial scan of virtual environments...
[I 17:13:00.116 LabApp] Found new kernels in environments: conda_caffe_p27, conda_cntk_p27, conda_caffe2_p27, conda_python3, conda_tensorflow_p36, conda_theano_p27, conda_mxnet_p27, conda_pytorch_p27, conda_mxnet_p36, conda_tensorflow_p27, conda_chainer_p27, conda_caffe_p35, conda_cntk_p36, conda_theano_p36, conda_anaconda3, conda_python2, conda_pytorch_p36, conda_chainer_p36
[W 17:13:00.128 LabApp] 404 GET /api/kernels/bf643ce3-07e0-4995-89cf-9a16400cc742/channels?session_id=95a656bb0e9d986f69c639f96ff503ec&token=03087412678bcbc8432f87ecd022d25262a54505f0b241cc (127.0.0.1): Kernel does not exist: bf643ce3-07e0-4995-89cf-9a16400cc742
[W 17:13:00.156 LabApp] 404 GET /api/kernels/bf643ce3-07e0-4995-89cf-9a16400cc742/channels?session_id=95a656bb0e9d986f69c639f96ff503ec&token=03087412678bcbc8432f87ecd022d25262a54505f0b241cc (127.0.0.1) 37.67ms referer=None
[W 17:13:01.739 LabApp] 404 GET /api/contents/zebrafish_passivity?content=1&1535389981661 (127.0.0.1): No such file or directory: zebrafish_passivity
[W 17:13:01.741 LabApp] No such file or directory: zebrafish_passivity
[W 17:13:01.742 LabApp] 404 GET /api/contents/zebrafish_passivity?content=1&1535389981661 (127.0.0.1) 5.68ms referer=http://localhost:8002/lab
[W 17:13:04.491 LabApp] 404 GET /api/kernels/f4cd877c-0621-495b-afb7-ee1fca616ccd/channels?session_id=a101d34f8c214992b59923b4d1cd9b59&token=03087412678bcbc8432f87ecd022d25262a54505f0b241cc (127.0.0.1): Kernel does not exist: f4cd877c-0621-495b-afb7-ee1fca616ccd
[W 17:13:04.492 LabApp] 404 GET /api/kernels/f4cd877c-0621-495b-afb7-ee1fca616ccd/channels?session_id=a101d34f8c214992b59923b4d1cd9b59&token=03087412678bcbc8432f87ecd022d25262a54505f0b241cc (127.0.0.1) 2.71ms referer=None
[W 17:13:07.827 LabApp] 404 GET /api/contents/zebrafish_passivity?1535389987769 (127.0.0.1): No such file or directory: zebrafish_passivity
[W 17:13:07.827 LabApp] No such file or directory: zebrafish_passivity
[W 17:13:07.827 LabApp] 404 GET /api/contents/zebrafish_passivity?1535389987769 (127.0.0.1) 1.10ms referer=http://localhost:8002/lab
[W 17:13:07.828 LabApp] 404 GET /api/contents/zebrafish_passivity/180823-fig.ipynb?content=0&1535389987770 (127.0.0.1): No such file or directory: zebrafish_passivity/180823-fig.ipynb
[W 17:13:07.828 LabApp] No such file or directory: zebrafish_passivity/180823-fig.ipynb
[W 17:13:07.828 LabApp] 404 GET /api/contents/zebrafish_passivity/180823-fig.ipynb?content=0&1535389987770 (127.0.0.1) 0.98ms referer=http://localhost:8002/lab
[W 17:13:07.829 LabApp] 404 GET /api/contents/zebrafish_passivity/viz_models_a.ipynb?content=0&1535389987770 (127.0.0.1): No such file or directory: zebrafish_passivity/viz_models_a.ipynb
[W 17:13:07.829 LabApp] No such file or directory: zebrafish_passivity/viz_models_a.ipynb
[W 17:13:07.830 LabApp] 404 GET /api/contents/zebrafish_passivity/viz_models_a.ipynb?content=0&1535389987770 (127.0.0.1) 0.94ms referer=http://localhost:8002/lab
[I 17:13:08.534 LabApp] Build is up to date
[W 17:13:20.295 LabApp] Notebook viz_models.ipynb is not trusted
[I 17:13:22.336 LabApp] Kernel started: 637ad101-be49-4bd5-ae23-26cc81a2b5d0
[I 17:13:24.107 LabApp] Adapting to protocol v5.1 for kernel 637ad101-be49-4bd5-ae23-26cc81a2b5d0
[I 17:13:24.291 LabApp] Adapting to protocol v5.1 for kernel 637ad101-be49-4bd5-ae23-26cc81a2b5d0
[I 17:13:24.367 LabApp] Kernel started: e55ac9b3-e544-42c0-bb3b-7c805ba21b64
[I 17:13:24.698 LabApp] Adapting to protocol v5.1 for kernel e55ac9b3-e544-42c0-bb3b-7c805ba21b64
[I 17:13:24.827 LabApp] Adapting to protocol v5.1 for kernel e55ac9b3-e544-42c0-bb3b-7c805ba21b64
[W 17:39:58.908 LabApp] Notebook 180823-fig.ipynb is not trusted
[I 17:40:01.770 LabApp] Kernel started: 4e610885-f263-40a6-a721-7bd036072440
[I 17:40:05.121 LabApp] Adapting to protocol v5.1 for kernel 4e610885-f263-40a6-a721-7bd036072440
[I 17:44:32.732 LabApp] Saving file at /180827_viz_models.ipynb
[W 17:44:32.733 LabApp] Notebook 180827_viz_models.ipynb is not trusted
[I 17:48:18.883 LabApp] Saving file at /180827_viz_models.ipynb
[W 17:48:18.883 LabApp] Notebook 180827_viz_models.ipynb is not trusted
[I 18:48:14.898 LabApp] Saving file at /180827_viz_models.ipynb
[W 18:48:14.899 LabApp] Notebook 180827_viz_models.ipynb is not trusted
[I 18:48:16.324 LabApp] Starting buffering for 4e610885-f263-40a6-a721-7bd036072440:7d5dee50a10f0683be0e940f52e839d8
[I 18:48:16.324 LabApp] Starting buffering for 637ad101-be49-4bd5-ae23-26cc81a2b5d0:dcc879ff4e8b607d6b25f9376ac47fcb
[I 18:48:16.325 LabApp] Starting buffering for e55ac9b3-e544-42c0-bb3b-7c805ba21b64:1779568e86312ef2d6fa77de682d5df3
[I 04:02:37.286 LabApp] 302 GET / (127.0.0.1) 0.81ms
[I 04:02:39.595 LabApp] Adapting to protocol v5.1 for kernel 4e610885-f263-40a6-a721-7bd036072440
[W 04:02:39.917 LabApp] Notebook 180827_viz_models.ipynb is not trusted
[I 04:02:40.031 LabApp] Starting buffering for 4e610885-f263-40a6-a721-7bd036072440:3af030c7707e8f63940d1fc1fc56d8e3
[I 04:02:40.149 LabApp] Build is up to date
[I 04:02:41.653 LabApp] Adapting to protocol v5.1 for kernel 637ad101-be49-4bd5-ae23-26cc81a2b5d0
[I 04:02:42.217 LabApp] Adapting to protocol v5.1 for kernel e55ac9b3-e544-42c0-bb3b-7c805ba21b64
[I 04:02:49.169 LabApp] Kernel shutdown: e55ac9b3-e544-42c0-bb3b-7c805ba21b64
[I 04:02:51.156 LabApp] Kernel shutdown: 637ad101-be49-4bd5-ae23-26cc81a2b5d0
[I 04:02:51.361 LabApp] Kernel shutdown: 4e610885-f263-40a6-a721-7bd036072440
[I 04:03:03.599 LabApp] Kernel started: 1dc4927c-2d42-498e-a2b8-f9311c665f18
[I 04:03:07.821 LabApp] Adapting to protocol v5.1 for kernel 1dc4927c-2d42-498e-a2b8-f9311c665f18
[I 04:03:43.552 LabApp] Saving file at /180827_viz_models.ipynb
[W 04:03:43.553 LabApp] Notebook 180827_viz_models.ipynb is not trusted
THCudaCheck FAIL file=/opt/conda/conda-bld/pytorch_1524577523076/work/aten/src/THC/generic/THCStorage.cu line=58 error=2 : out of memory
[I 04:29:07.243 LabApp] Kernel interrupted: 1dc4927c-2d42-498e-a2b8-f9311c665f18
[I 04:29:41.066 LabApp] Starting buffering for 1dc4927c-2d42-498e-a2b8-f9311c665f18:50fa48ca5d5676059959998296db48bb
[I 04:29:42.678 LabApp] Kernel restarted: 1dc4927c-2d42-498e-a2b8-f9311c665f18
[I 04:29:43.228 LabApp] Adapting to protocol v5.1 for kernel 1dc4927c-2d42-498e-a2b8-f9311c665f18
[I 04:29:43.228 LabApp] Restoring connection for 1dc4927c-2d42-498e-a2b8-f9311c665f18:50fa48ca5d5676059959998296db48bb
[I 04:29:43.228 LabApp] Replaying 5 buffered messages
[I 04:34:40.483 LabApp] Kernel interrupted: 1dc4927c-2d42-498e-a2b8-f9311c665f18
THCudaCheck FAIL file=/opt/conda/conda-bld/pytorch_1524577523076/work/aten/src/THC/generic/THCStorage.cu line=58 error=2 : out of memory
[I 04:38:56.282 LabApp] Kernel interrupted: 1dc4927c-2d42-498e-a2b8-f9311c665f18
[I 04:47:10.273 LabApp] Saving file at /180827_viz_models.ipynb
[W 04:47:10.274 LabApp] Notebook 180827_viz_models.ipynb is not trusted
[I 04:57:58.939 LabApp] Saving file at /180827_viz_models.ipynb
[W 04:57:58.940 LabApp] Notebook 180827_viz_models.ipynb is not trusted
[I 05:09:59.022 LabApp] Starting buffering for 1dc4927c-2d42-498e-a2b8-f9311c665f18:50fa48ca5d5676059959998296db48bb
[I 05:09:59.533 LabApp] Kernel restarted: 1dc4927c-2d42-498e-a2b8-f9311c665f18
[I 05:10:00.021 LabApp] Adapting to protocol v5.1 for kernel 1dc4927c-2d42-498e-a2b8-f9311c665f18
[I 05:10:00.022 LabApp] Restoring connection for 1dc4927c-2d42-498e-a2b8-f9311c665f18:50fa48ca5d5676059959998296db48bb
[I 05:10:00.022 LabApp] Replaying 6 buffered messages
THCudaCheck FAIL file=/opt/conda/conda-bld/pytorch_1524577523076/work/aten/src/THC/generic/THCStorage.cu line=58 error=2 : out of memory
[I 05:15:03.135 LabApp] Starting buffering for 1dc4927c-2d42-498e-a2b8-f9311c665f18:50fa48ca5d5676059959998296db48bb
[I 05:15:03.784 LabApp] Kernel restarted: 1dc4927c-2d42-498e-a2b8-f9311c665f18
[I 05:15:04.235 LabApp] Adapting to protocol v5.1 for kernel 1dc4927c-2d42-498e-a2b8-f9311c665f18
[I 05:15:04.236 LabApp] Restoring connection for 1dc4927c-2d42-498e-a2b8-f9311c665f18:50fa48ca5d5676059959998296db48bb
[I 05:15:04.236 LabApp] Replaying 6 buffered messages
[I 05:15:26.394 LabApp] Kernel interrupted: 1dc4927c-2d42-498e-a2b8-f9311c665f18
[I 05:20:34.478 LabApp] Kernel interrupted: 1dc4927c-2d42-498e-a2b8-f9311c665f18
[I 05:20:43.374 LabApp] Kernel interrupted: 1dc4927c-2d42-498e-a2b8-f9311c665f18
[I 05:20:44.629 LabApp] Kernel interrupted: 1dc4927c-2d42-498e-a2b8-f9311c665f18
[I 05:20:45.578 LabApp] Starting buffering for 1dc4927c-2d42-498e-a2b8-f9311c665f18:50fa48ca5d5676059959998296db48bb
[I 05:20:50.864 LabApp] Kernel restarted: 1dc4927c-2d42-498e-a2b8-f9311c665f18
[I 05:20:51.332 LabApp] Kernel restarted: 1dc4927c-2d42-498e-a2b8-f9311c665f18
[I 05:20:52.193 LabApp] Adapting to protocol v5.1 for kernel 1dc4927c-2d42-498e-a2b8-f9311c665f18
[I 05:20:52.194 LabApp] Restoring connection for 1dc4927c-2d42-498e-a2b8-f9311c665f18:50fa48ca5d5676059959998296db48bb
[I 05:20:52.194 LabApp] Replaying 9 buffered messages
[I 05:20:52.312 LabApp] Starting buffering for 1dc4927c-2d42-498e-a2b8-f9311c665f18:50fa48ca5d5676059959998296db48bb
[I 05:20:52.319 LabApp] Saving file at /180827_viz_models.ipynb
[W 05:20:52.320 LabApp] Notebook 180827_viz_models.ipynb is not trusted
[I 05:20:52.607 LabApp] Adapting to protocol v5.1 for kernel 1dc4927c-2d42-498e-a2b8-f9311c665f18
[I 05:20:52.608 LabApp] Restoring connection for 1dc4927c-2d42-498e-a2b8-f9311c665f18:50fa48ca5d5676059959998296db48bb
[I 05:29:05.837 LabApp] Saving file at /180827_viz_models.ipynb
[W 05:29:05.838 LabApp] Notebook 180827_viz_models.ipynb is not trusted
[W 05:30:39.208 LabApp] Notebook 180827_viz_models.ipynb is not trusted
[I 05:30:40.897 LabApp] Adapting to protocol v5.1 for kernel 1dc4927c-2d42-498e-a2b8-f9311c665f18
[I 05:32:26.270 LabApp] Starting buffering for 1dc4927c-2d42-498e-a2b8-f9311c665f18:692475dc18c7ce6950db74c3b9cb34be
[I 05:32:27.081 LabApp] Kernel restarted: 1dc4927c-2d42-498e-a2b8-f9311c665f18
[I 05:32:27.586 LabApp] Adapting to protocol v5.1 for kernel 1dc4927c-2d42-498e-a2b8-f9311c665f18
[I 05:32:27.587 LabApp] Discarding 6 buffered messages for 1dc4927c-2d42-498e-a2b8-f9311c665f18:692475dc18c7ce6950db74c3b9cb34be
[I 05:32:27.718 LabApp] Adapting to protocol v5.1 for kernel 1dc4927c-2d42-498e-a2b8-f9311c665f18
[I 06:02:16.692 LabApp] Saving file at /180827_viz_models.ipynb
[W 06:02:16.694 LabApp] Notebook 180827_viz_models.ipynb is not trusted
[I 06:02:19.752 LabApp] Starting buffering for 1dc4927c-2d42-498e-a2b8-f9311c665f18:692475dc18c7ce6950db74c3b9cb34be
[I 06:02:20.263 LabApp] Kernel restarted: 1dc4927c-2d42-498e-a2b8-f9311c665f18
[I 06:02:20.722 LabApp] Adapting to protocol v5.1 for kernel 1dc4927c-2d42-498e-a2b8-f9311c665f18
[I 06:02:20.723 LabApp] Discarding 3 buffered messages for 1dc4927c-2d42-498e-a2b8-f9311c665f18:692475dc18c7ce6950db74c3b9cb34be
[I 06:02:20.851 LabApp] Adapting to protocol v5.1 for kernel 1dc4927c-2d42-498e-a2b8-f9311c665f18
[I 19:24:35.554 LabApp] 302 GET / (127.0.0.1) 0.69ms
[W 19:24:37.680 LabApp] 404 GET /api/contents/rsync?1535570677197 (127.0.0.1): No such file or directory: rsync
[W 19:24:37.681 LabApp] No such file or directory: rsync
[W 19:24:37.681 LabApp] 404 GET /api/contents/rsync?1535570677197 (127.0.0.1) 3.37ms referer=http://localhost:8002/lab?
[W 19:24:37.682 LabApp] 404 GET /api/contents/rsync/180824-sparse_skip.ipynb?content=0&1535570677199 (127.0.0.1): No such file or directory: rsync/180824-sparse_skip.ipynb
[W 19:24:37.682 LabApp] No such file or directory: rsync/180824-sparse_skip.ipynb
[W 19:24:37.682 LabApp] 404 GET /api/contents/rsync/180824-sparse_skip.ipynb?content=0&1535570677199 (127.0.0.1) 0.96ms referer=http://localhost:8002/lab?
[W 19:24:37.683 LabApp] 404 GET /api/contents/rsync/180824-cross-valid_predicting_NOFIX.ipynb?content=0&1535570677201 (127.0.0.1): No such file or directory: rsync/180824-cross-valid_predicting_NOFIX.ipynb
[W 19:24:37.684 LabApp] No such file or directory: rsync/180824-cross-valid_predicting_NOFIX.ipynb
[W 19:24:37.684 LabApp] 404 GET /api/contents/rsync/180824-cross-valid_predicting_NOFIX.ipynb?content=0&1535570677201 (127.0.0.1) 0.95ms referer=http://localhost:8002/lab?
[W 19:24:37.685 LabApp] 404 GET /api/contents/rsync/180822-cross-valid_predicting!.ipynb?content=0&1535570677199 (127.0.0.1): No such file or directory: rsync/180822-cross-valid_predicting!.ipynb
[W 19:24:37.685 LabApp] No such file or directory: rsync/180822-cross-valid_predicting!.ipynb
[W 19:24:37.685 LabApp] 404 GET /api/contents/rsync/180822-cross-valid_predicting!.ipynb?content=0&1535570677199 (127.0.0.1) 0.94ms referer=http://localhost:8002/lab?
[W 19:24:37.686 LabApp] 404 GET /api/contents/rsync/180821-Deep_KSVD.ipynb?content=0&1535570677201 (127.0.0.1): No such file or directory: rsync/180821-Deep_KSVD.ipynb
[W 19:24:37.686 LabApp] No such file or directory: rsync/180821-Deep_KSVD.ipynb
[W 19:24:37.686 LabApp] 404 GET /api/contents/rsync/180821-Deep_KSVD.ipynb?content=0&1535570677201 (127.0.0.1) 0.94ms referer=http://localhost:8002/lab?
[I 19:24:37.744 LabApp] Adapting to protocol v5.1 for kernel 1dc4927c-2d42-498e-a2b8-f9311c665f18
[W 19:24:37.761 LabApp] 404 GET /api/contents/rsync/180824-cross-valid_predicting!_resnet_fix-Copy1.ipynb?content=0&1535570677204 (127.0.0.1): No such file or directory: rsync/180824-cross-valid_predicting!_resnet_fix-Copy1.ipynb
[W 19:24:37.761 LabApp] No such file or directory: rsync/180824-cross-valid_predicting!_resnet_fix-Copy1.ipynb
[W 19:24:37.761 LabApp] 404 GET /api/contents/rsync/180824-cross-valid_predicting!_resnet_fix-Copy1.ipynb?content=0&1535570677204 (127.0.0.1) 0.99ms referer=http://localhost:8002/lab?
[W 19:24:37.764 LabApp] 404 GET /api/contents/zebrafish_passivity/180823-fig.ipynb?content=0&1535570677203 (127.0.0.1): No such file or directory: zebrafish_passivity/180823-fig.ipynb
[W 19:24:37.764 LabApp] No such file or directory: zebrafish_passivity/180823-fig.ipynb
[W 19:24:37.765 LabApp] 404 GET /api/contents/zebrafish_passivity/180823-fig.ipynb?content=0&1535570677203 (127.0.0.1) 2.94ms referer=http://localhost:8002/lab?
[W 19:24:37.768 LabApp] 404 GET /api/contents/rsync/180724-skip.ipynb?content=0&1535570677204 (127.0.0.1): No such file or directory: rsync/180724-skip.ipynb
[W 19:24:37.768 LabApp] No such file or directory: rsync/180724-skip.ipynb
[W 19:24:37.769 LabApp] 404 GET /api/contents/rsync/180724-skip.ipynb?content=0&1535570677204 (127.0.0.1) 3.33ms referer=http://localhost:8002/lab?
[W 19:24:37.770 LabApp] 404 GET /api/contents/zebrafish_passivity/viz_models.ipynb?content=0&1535570677205 (127.0.0.1): No such file or directory: zebrafish_passivity/viz_models.ipynb
[W 19:24:37.770 LabApp] No such file or directory: zebrafish_passivity/viz_models.ipynb
[W 19:24:37.770 LabApp] 404 GET /api/contents/zebrafish_passivity/viz_models.ipynb?content=0&1535570677205 (127.0.0.1) 0.96ms referer=http://localhost:8002/lab?
[W 19:24:37.771 LabApp] 404 GET /api/contents/rsync/180823-sparse_skip-Copy1.ipynb?content=0&1535570677206 (127.0.0.1): No such file or directory: rsync/180823-sparse_skip-Copy1.ipynb
[W 19:24:37.771 LabApp] No such file or directory: rsync/180823-sparse_skip-Copy1.ipynb
[W 19:24:37.771 LabApp] 404 GET /api/contents/rsync/180823-sparse_skip-Copy1.ipynb?content=0&1535570677206 (127.0.0.1) 0.95ms referer=http://localhost:8002/lab?
[W 19:24:37.843 LabApp] 404 GET /api/contents/rsync/180724-bam.ipynb?content=0&1535570677208 (127.0.0.1): No such file or directory: rsync/180724-bam.ipynb
[W 19:24:37.844 LabApp] No such file or directory: rsync/180724-bam.ipynb
[W 19:24:37.844 LabApp] 404 GET /api/contents/rsync/180724-bam.ipynb?content=0&1535570677208 (127.0.0.1) 1.01ms referer=http://localhost:8002/lab?
[I 19:24:38.349 LabApp] Build is up to date
[W 19:42:44.481 LabApp] Notebook 180827_viz_models.ipynb is not trusted
[I 19:42:46.423 LabApp] Adapting to protocol v5.1 for kernel 1dc4927c-2d42-498e-a2b8-f9311c665f18
[I 21:00:04.004 LabApp] Adapting to protocol v5.1 for kernel 1dc4927c-2d42-498e-a2b8-f9311c665f18
[W 21:37:34.052 LabApp] WebSocket ping timeout after 119916 ms.
[I 03:44:49.990 LabApp] Starting buffering for 1dc4927c-2d42-498e-a2b8-f9311c665f18:692475dc18c7ce6950db74c3b9cb34be
[C 04:30:55.221 LabApp] received signal 15, stopping
[I 04:30:55.224 LabApp] Shutting down 1 kernel
[I 04:30:55.340 LabApp] Kernel shutdown: 1dc4927c-2d42-498e-a2b8-f9311c665f18
[I 17:50:18.971 LabApp] Using EnvironmentKernelSpecManager...
[I 17:50:18.972 LabApp] Started periodic updates of the kernel list (every 3 minutes).
[I 17:50:19.158 LabApp] JupyterLab beta preview extension loaded from /home/ubuntu/anaconda3/lib/python3.6/site-packages/jupyterlab
[I 17:50:19.158 LabApp] JupyterLab application directory is /home/ubuntu/anaconda3/share/jupyter/lab
[I 17:50:19.333 LabApp] [nb_conda] enabled
/home/ubuntu/anaconda3/lib/python3.6/site-packages/matplotlib/__init__.py:1067: UserWarning: Duplicate key in file "/home/ubuntu/.config/matplotlib/matplotlibrc", line #2
  (fname, cnt))
/home/ubuntu/anaconda3/lib/python3.6/site-packages/matplotlib/__init__.py:1067: UserWarning: Duplicate key in file "/home/ubuntu/.config/matplotlib/matplotlibrc", line #3
  (fname, cnt))
[I 17:50:19.648 LabApp] sparkmagic extension enabled!
[I 17:50:19.650 LabApp] Serving notebooks from local directory: /data2/Code/zebrafish_passivity
[I 17:50:19.650 LabApp] 0 active kernels
[I 17:50:19.650 LabApp] The Jupyter Notebook is running at:
[I 17:50:19.650 LabApp] http://localhost:8002/?token=051901a29b3b3c0b6f9177d990b763eef101ab35c33a0b82
[I 17:50:19.650 LabApp] Use Control-C to stop this server and shut down all kernels (twice to skip confirmation).
[C 17:50:19.651 LabApp] 
    
    Copy/paste this URL into your browser when you connect for the first time,
    to login with a token:
        http://localhost:8002/?token=051901a29b3b3c0b6f9177d990b763eef101ab35c33a0b82&token=051901a29b3b3c0b6f9177d990b763eef101ab35c33a0b82
[I 17:50:19.651 LabApp] Starting initial scan of virtual environments...
[I 17:50:22.377 LabApp] Found new kernels in environments: conda_tf_27, conda_theano_p36, conda_python3, conda_pytorch_p36, conda_caffe2_p27, conda_tensorflow_p36, conda_pytorch_p27, conda_caffe_p35, conda_cntk_p27, conda_python2, conda_tensorflow_p27, conda_caffe_p27, conda_mxnet_p27, conda_theano_p27, conda_cntk_p36, conda_chainer_p36, conda_mxnet_p36, conda_chainer_p27, conda_anaconda3
[W 17:50:22.392 LabApp] 404 GET /api/kernels/28ffb688-b3de-4ec3-959a-fbce15ef5801/channels?session_id=40eceddd7839ef1b09feabaa5933501b&token=71179e987d87f354abe7aeff254074e19aec7282f5a85602 (127.0.0.1): Kernel does not exist: 28ffb688-b3de-4ec3-959a-fbce15ef5801
[W 17:50:22.418 LabApp] 404 GET /api/kernels/28ffb688-b3de-4ec3-959a-fbce15ef5801/channels?session_id=40eceddd7839ef1b09feabaa5933501b&token=71179e987d87f354abe7aeff254074e19aec7282f5a85602 (127.0.0.1) 35.58ms referer=None
[W 17:50:37.668 LabApp] 404 GET /api/contents/Code/zebrafish_passivity?1539366637636 (127.0.0.1): No such file or directory: Code/zebrafish_passivity
[W 17:50:37.668 LabApp] No such file or directory: Code/zebrafish_passivity
[W 17:50:37.668 LabApp] 404 GET /api/contents/Code/zebrafish_passivity?1539366637636 (127.0.0.1) 3.27ms referer=http://localhost:8002/lab
[W 17:50:37.669 LabApp] 404 GET /api/contents/Code/zebrafish_passivity/181011_PCA_granger_all.ipynb?content=0&1539366637638 (127.0.0.1): No such file or directory: Code/zebrafish_passivity/181011_PCA_granger_all.ipynb
[W 17:50:37.669 LabApp] No such file or directory: Code/zebrafish_passivity/181011_PCA_granger_all.ipynb
[W 17:50:37.669 LabApp] 404 GET /api/contents/Code/zebrafish_passivity/181011_PCA_granger_all.ipynb?content=0&1539366637638 (127.0.0.1) 0.95ms referer=http://localhost:8002/lab
[W 17:50:37.673 LabApp] 404 GET /api/contents/Code/zebrafish_passivity/181012_aaron_helper.ipynb?content=0&1539366637638 (127.0.0.1): No such file or directory: Code/zebrafish_passivity/181012_aaron_helper.ipynb
[W 17:50:37.673 LabApp] No such file or directory: Code/zebrafish_passivity/181012_aaron_helper.ipynb
[W 17:50:37.673 LabApp] 404 GET /api/contents/Code/zebrafish_passivity/181012_aaron_helper.ipynb?content=0&1539366637638 (127.0.0.1) 0.95ms referer=http://localhost:8002/lab
[W 17:50:37.674 LabApp] 404 GET /api/contents/Code/zebrafish_passivity/181002_tf.ipynb?content=0&1539366637639 (127.0.0.1): No such file or directory: Code/zebrafish_passivity/181002_tf.ipynb
[W 17:50:37.674 LabApp] No such file or directory: Code/zebrafish_passivity/181002_tf.ipynb
[W 17:50:37.675 LabApp] 404 GET /api/contents/Code/zebrafish_passivity/181002_tf.ipynb?content=0&1539366637639 (127.0.0.1) 0.93ms referer=http://localhost:8002/lab
[I 17:50:38.183 LabApp] Build is up to date
[W 17:51:02.815 LabApp] Notebook 181012_aaron_helper.ipynb is not trusted
[E 17:51:08.926 LabApp] Couldn't get environment variables for commands: ['source', 'activate', '/home/ubuntu/anaconda3/envs/tensorflow_p27']
    Traceback (most recent call last):
      File "/home/ubuntu/anaconda3/lib/python3.6/site-packages/environment_kernels/activate_helper.py", line 61, in source_env_vars_from_command
        return source_bash(args)
      File "/home/ubuntu/anaconda3/lib/python3.6/site-packages/environment_kernels/activate_helper.py", line 73, in source_bash
        return source_foreign(new_args, stdin=stdin)
      File "/home/ubuntu/anaconda3/lib/python3.6/site-packages/environment_kernels/activate_helper.py", line 191, in source_foreign
        seterrpostcmd=ns.seterrpostcmd)
      File "/home/ubuntu/anaconda3/lib/python3.6/site-packages/environment_kernels/activate_helper.py", line 433, in foreign_shell_data
        universal_newlines=True)
      File "/home/ubuntu/anaconda3/lib/python3.6/subprocess.py", line 336, in check_output
        **kwargs).stdout
      File "/home/ubuntu/anaconda3/lib/python3.6/subprocess.py", line 418, in run
        output=stdout, stderr=stderr)
    subprocess.CalledProcessError: Command '['bash', '-i', '-c', 'set -e\nsource activate /home/ubuntu/anaconda3/envs/tensorflow_p27\necho __XONSH_ENV_BEG__\nenv\necho __XONSH_ENV_END__']' returned non-zero exit status 1.
    
    During handling of the above exception, another exception occurred:
    
    Traceback (most recent call last):
      File "/home/ubuntu/anaconda3/lib/python3.6/site-packages/environment_kernels/envs_conda.py", line 52, in _get_env_vars_for_conda_env
        envs = source_env_vars_from_command(args)
      File "/home/ubuntu/anaconda3/lib/python3.6/site-packages/environment_kernels/activate_helper.py", line 63, in source_env_vars_from_command
        return source_zsh(args)
      File "/home/ubuntu/anaconda3/lib/python3.6/site-packages/environment_kernels/activate_helper.py", line 82, in source_zsh
        return source_foreign(new_args, stdin=stdin)
      File "/home/ubuntu/anaconda3/lib/python3.6/site-packages/environment_kernels/activate_helper.py", line 191, in source_foreign
        seterrpostcmd=ns.seterrpostcmd)
      File "/home/ubuntu/anaconda3/lib/python3.6/site-packages/environment_kernels/activate_helper.py", line 433, in foreign_shell_data
        universal_newlines=True)
      File "/home/ubuntu/anaconda3/lib/python3.6/subprocess.py", line 336, in check_output
        **kwargs).stdout
      File "/home/ubuntu/anaconda3/lib/python3.6/subprocess.py", line 418, in run
        output=stdout, stderr=stderr)
    subprocess.CalledProcessError: Command '['zsh', '-i', '-c', 'set -e\nsource activate /home/ubuntu/anaconda3/envs/tensorflow_p27\necho __XONSH_ENV_BEG__\nenv\necho __XONSH_ENV_END__']' returned non-zero exit status 127.
[I 17:51:08.936 LabApp] Kernel started: b9ff9c4c-d224-4a57-882d-c37f09241391
[I 17:51:09.263 LabApp] Adapting to protocol v5.1 for kernel b9ff9c4c-d224-4a57-882d-c37f09241391
[I 17:51:09.420 LabApp] Adapting to protocol v5.1 for kernel b9ff9c4c-d224-4a57-882d-c37f09241391
[I 17:51:09.548 LabApp] Adapting to protocol v5.1 for kernel b9ff9c4c-d224-4a57-882d-c37f09241391
2018-10-12 17:51:35.512808: I tensorflow/core/platform/cpu_feature_guard.cc:141] Your CPU supports instructions that this TensorFlow binary was not compiled to use: AVX2 FMA
2018-10-12 17:51:35.532909: I tensorflow/core/common_runtime/gpu/gpu_device.cc:971] Device interconnect StreamExecutor with strength 1 edge matrix:
2018-10-12 17:51:35.532930: I tensorflow/core/common_runtime/gpu/gpu_device.cc:977]      
2018-10-12 17:51:35.612476: I tensorflow/core/common_runtime/gpu/gpu_device.cc:971] Device interconnect StreamExecutor with strength 1 edge matrix:
2018-10-12 17:51:35.612511: I tensorflow/core/common_runtime/gpu/gpu_device.cc:977]      
[I 17:51:52.153 LabApp] Saving file at /181012_aaron_helper.ipynb
[W 17:51:52.155 LabApp] Notebook 181012_aaron_helper.ipynb is not trusted
[I 17:55:42.356 LabApp] Saving file at /181012_aaron_helper.ipynb
[W 17:55:42.358 LabApp] Notebook 181012_aaron_helper.ipynb is not trusted
[I 17:55:48.319 LabApp] Shutting down on /api/shutdown request.
[I 17:55:48.321 LabApp] Shutting down 1 kernel
[I 17:55:48.923 LabApp] Kernel shutdown: b9ff9c4c-d224-4a57-882d-c37f09241391
[I 17:55:51.306 LabApp] Using EnvironmentKernelSpecManager...
[I 17:55:51.306 LabApp] Started periodic updates of the kernel list (every 3 minutes).
[I 17:55:51.492 LabApp] JupyterLab beta preview extension loaded from /home/ubuntu/anaconda3/lib/python3.6/site-packages/jupyterlab
[I 17:55:51.492 LabApp] JupyterLab application directory is /home/ubuntu/anaconda3/share/jupyter/lab
[I 17:55:51.667 LabApp] [nb_conda] enabled
/home/ubuntu/anaconda3/lib/python3.6/site-packages/matplotlib/__init__.py:1067: UserWarning: Duplicate key in file "/home/ubuntu/.config/matplotlib/matplotlibrc", line #2
  (fname, cnt))
/home/ubuntu/anaconda3/lib/python3.6/site-packages/matplotlib/__init__.py:1067: UserWarning: Duplicate key in file "/home/ubuntu/.config/matplotlib/matplotlibrc", line #3
  (fname, cnt))
[I 17:55:51.979 LabApp] sparkmagic extension enabled!
[I 17:55:51.981 LabApp] Serving notebooks from local directory: /data2/Code/zebrafish_passivity
[I 17:55:51.981 LabApp] 0 active kernels
[I 17:55:51.981 LabApp] The Jupyter Notebook is running at:
[I 17:55:51.981 LabApp] http://localhost:8002/?token=cbd34b4af93838d197946b5f161285a7fa3614bf0acdc246
[I 17:55:51.981 LabApp] Use Control-C to stop this server and shut down all kernels (twice to skip confirmation).
[C 17:55:51.981 LabApp] 
    
    Copy/paste this URL into your browser when you connect for the first time,
    to login with a token:
        http://localhost:8002/?token=cbd34b4af93838d197946b5f161285a7fa3614bf0acdc246&token=cbd34b4af93838d197946b5f161285a7fa3614bf0acdc246
[I 17:55:51.981 LabApp] Starting initial scan of virtual environments...
[I 17:55:54.662 LabApp] Found new kernels in environments: conda_mxnet_p36, conda_tensorflow_p36, conda_cntk_p36, conda_python3, conda_pytorch_p27, conda_theano_p36, conda_chainer_p36, conda_caffe_p27, conda_anaconda3, conda_caffe_p35, conda_python2, conda_caffe2_p27, conda_chainer_p27, conda_tensorflow_p27, conda_tf_27, conda_mxnet_p27, conda_pytorch_p36, conda_theano_p27, conda_cntk_p27
[W 17:55:54.673 LabApp] 404 GET /api/kernels/b9ff9c4c-d224-4a57-882d-c37f09241391/channels?session_id=3af73410f348ea13391afc118feca82b&token=051901a29b3b3c0b6f9177d990b763eef101ab35c33a0b82 (127.0.0.1): Kernel does not exist: b9ff9c4c-d224-4a57-882d-c37f09241391
[W 17:55:54.699 LabApp] 404 GET /api/kernels/b9ff9c4c-d224-4a57-882d-c37f09241391/channels?session_id=3af73410f348ea13391afc118feca82b&token=051901a29b3b3c0b6f9177d990b763eef101ab35c33a0b82 (127.0.0.1) 35.19ms referer=None
[W 17:55:57.648 LabApp] Notebook 181012_aaron_helper.ipynb is not trusted
[I 17:55:57.875 LabApp] Build is up to date
[E 17:56:04.362 LabApp] Couldn't get environment variables for commands: ['source', 'activate', '/home/ubuntu/anaconda3/envs/tensorflow_p27']
    Traceback (most recent call last):
      File "/home/ubuntu/anaconda3/lib/python3.6/site-packages/environment_kernels/activate_helper.py", line 61, in source_env_vars_from_command
        return source_bash(args)
      File "/home/ubuntu/anaconda3/lib/python3.6/site-packages/environment_kernels/activate_helper.py", line 73, in source_bash
        return source_foreign(new_args, stdin=stdin)
      File "/home/ubuntu/anaconda3/lib/python3.6/site-packages/environment_kernels/activate_helper.py", line 191, in source_foreign
        seterrpostcmd=ns.seterrpostcmd)
      File "/home/ubuntu/anaconda3/lib/python3.6/site-packages/environment_kernels/activate_helper.py", line 433, in foreign_shell_data
        universal_newlines=True)
      File "/home/ubuntu/anaconda3/lib/python3.6/subprocess.py", line 336, in check_output
        **kwargs).stdout
      File "/home/ubuntu/anaconda3/lib/python3.6/subprocess.py", line 418, in run
        output=stdout, stderr=stderr)
    subprocess.CalledProcessError: Command '['bash', '-i', '-c', 'set -e\nsource activate /home/ubuntu/anaconda3/envs/tensorflow_p27\necho __XONSH_ENV_BEG__\nenv\necho __XONSH_ENV_END__']' returned non-zero exit status 1.
    
    During handling of the above exception, another exception occurred:
    
    Traceback (most recent call last):
      File "/home/ubuntu/anaconda3/lib/python3.6/site-packages/environment_kernels/envs_conda.py", line 52, in _get_env_vars_for_conda_env
        envs = source_env_vars_from_command(args)
      File "/home/ubuntu/anaconda3/lib/python3.6/site-packages/environment_kernels/activate_helper.py", line 63, in source_env_vars_from_command
        return source_zsh(args)
      File "/home/ubuntu/anaconda3/lib/python3.6/site-packages/environment_kernels/activate_helper.py", line 82, in source_zsh
        return source_foreign(new_args, stdin=stdin)
      File "/home/ubuntu/anaconda3/lib/python3.6/site-packages/environment_kernels/activate_helper.py", line 191, in source_foreign
        seterrpostcmd=ns.seterrpostcmd)
      File "/home/ubuntu/anaconda3/lib/python3.6/site-packages/environment_kernels/activate_helper.py", line 433, in foreign_shell_data
        universal_newlines=True)
      File "/home/ubuntu/anaconda3/lib/python3.6/subprocess.py", line 336, in check_output
        **kwargs).stdout
      File "/home/ubuntu/anaconda3/lib/python3.6/subprocess.py", line 418, in run
        output=stdout, stderr=stderr)
    subprocess.CalledProcessError: Command '['zsh', '-i', '-c', 'set -e\nsource activate /home/ubuntu/anaconda3/envs/tensorflow_p27\necho __XONSH_ENV_BEG__\nenv\necho __XONSH_ENV_END__']' returned non-zero exit status 127.
[I 17:56:04.370 LabApp] Kernel started: bb9af98f-38e7-4c15-a41c-7b5142d7fefa
[I 17:56:04.698 LabApp] Adapting to protocol v5.1 for kernel bb9af98f-38e7-4c15-a41c-7b5142d7fefa
[I 17:56:04.826 LabApp] Adapting to protocol v5.1 for kernel bb9af98f-38e7-4c15-a41c-7b5142d7fefa
2018-10-12 17:56:35.879609: I tensorflow/core/platform/cpu_feature_guard.cc:141] Your CPU supports instructions that this TensorFlow binary was not compiled to use: AVX2 FMA
2018-10-12 17:56:35.901228: I tensorflow/core/common_runtime/gpu/gpu_device.cc:971] Device interconnect StreamExecutor with strength 1 edge matrix:
2018-10-12 17:56:35.901247: I tensorflow/core/common_runtime/gpu/gpu_device.cc:977]      
2018-10-12 17:56:35.977950: I tensorflow/core/common_runtime/gpu/gpu_device.cc:971] Device interconnect StreamExecutor with strength 1 edge matrix:
2018-10-12 17:56:35.977994: I tensorflow/core/common_runtime/gpu/gpu_device.cc:977]      
[W 18:11:12.160 LabApp] Notebook granger causality-helius.ipynb is not trusted
[I 18:11:14.611 LabApp] Kernel started: 3f87dee7-d886-49c8-b570-eaa8a118fe83
[I 18:11:14.940 LabApp] Adapting to protocol v5.1 for kernel 3f87dee7-d886-49c8-b570-eaa8a118fe83
[I 18:11:15.070 LabApp] Adapting to protocol v5.1 for kernel 3f87dee7-d886-49c8-b570-eaa8a118fe83
2018-10-12 18:30:15.632372: I tensorflow/core/common_runtime/gpu/gpu_device.cc:971] Device interconnect StreamExecutor with strength 1 edge matrix:
2018-10-12 18:30:15.632405: I tensorflow/core/common_runtime/gpu/gpu_device.cc:977]      
2018-10-12 18:30:16.029889: I tensorflow/core/common_runtime/gpu/gpu_device.cc:971] Device interconnect StreamExecutor with strength 1 edge matrix:
2018-10-12 18:30:16.031861: I tensorflow/core/common_runtime/gpu/gpu_device.cc:977]      
[I 18:44:45.902 LabApp] Saving file at /181012_aaron_helper.ipynb
[W 18:44:45.903 LabApp] Notebook 181012_aaron_helper.ipynb is not trusted
[W 19:17:04.130 LabApp] Notebook granger causality-helius.ipynb is not trusted
[I 19:17:06.536 LabApp] Adapting to protocol v5.1 for kernel 3f87dee7-d886-49c8-b570-eaa8a118fe83
[I 19:51:46.759 LabApp] Saving file at /181012_aaron_helper.ipynb
[W 19:51:46.761 LabApp] Notebook 181012_aaron_helper.ipynb is not trusted
[E 20:00:36.556 LabApp] Couldn't get environment variables for commands: ['source', 'activate', '/home/ubuntu/anaconda3/envs/tensorflow_p27']
    Traceback (most recent call last):
      File "/home/ubuntu/anaconda3/lib/python3.6/site-packages/environment_kernels/activate_helper.py", line 61, in source_env_vars_from_command
        return source_bash(args)
      File "/home/ubuntu/anaconda3/lib/python3.6/site-packages/environment_kernels/activate_helper.py", line 73, in source_bash
        return source_foreign(new_args, stdin=stdin)
      File "/home/ubuntu/anaconda3/lib/python3.6/site-packages/environment_kernels/activate_helper.py", line 191, in source_foreign
        seterrpostcmd=ns.seterrpostcmd)
      File "/home/ubuntu/anaconda3/lib/python3.6/site-packages/environment_kernels/activate_helper.py", line 433, in foreign_shell_data
        universal_newlines=True)
      File "/home/ubuntu/anaconda3/lib/python3.6/subprocess.py", line 336, in check_output
        **kwargs).stdout
      File "/home/ubuntu/anaconda3/lib/python3.6/subprocess.py", line 418, in run
        output=stdout, stderr=stderr)
    subprocess.CalledProcessError: Command '['bash', '-i', '-c', 'set -e\nsource activate /home/ubuntu/anaconda3/envs/tensorflow_p27\necho __XONSH_ENV_BEG__\nenv\necho __XONSH_ENV_END__']' returned non-zero exit status 1.
    
    During handling of the above exception, another exception occurred:
    
    Traceback (most recent call last):
      File "/home/ubuntu/anaconda3/lib/python3.6/site-packages/environment_kernels/envs_conda.py", line 52, in _get_env_vars_for_conda_env
        envs = source_env_vars_from_command(args)
      File "/home/ubuntu/anaconda3/lib/python3.6/site-packages/environment_kernels/activate_helper.py", line 63, in source_env_vars_from_command
        return source_zsh(args)
      File "/home/ubuntu/anaconda3/lib/python3.6/site-packages/environment_kernels/activate_helper.py", line 82, in source_zsh
        return source_foreign(new_args, stdin=stdin)
      File "/home/ubuntu/anaconda3/lib/python3.6/site-packages/environment_kernels/activate_helper.py", line 191, in source_foreign
        seterrpostcmd=ns.seterrpostcmd)
      File "/home/ubuntu/anaconda3/lib/python3.6/site-packages/environment_kernels/activate_helper.py", line 433, in foreign_shell_data
        universal_newlines=True)
      File "/home/ubuntu/anaconda3/lib/python3.6/subprocess.py", line 336, in check_output
        **kwargs).stdout
      File "/home/ubuntu/anaconda3/lib/python3.6/subprocess.py", line 418, in run
        output=stdout, stderr=stderr)
    subprocess.CalledProcessError: Command '['zsh', '-i', '-c', 'set -e\nsource activate /home/ubuntu/anaconda3/envs/tensorflow_p27\necho __XONSH_ENV_BEG__\nenv\necho __XONSH_ENV_END__']' returned non-zero exit status 127.
[I 20:00:36.564 LabApp] Kernel started: f4d1cc31-78f0-4200-9439-2f0bba6365b5
[I 20:00:36.899 LabApp] Adapting to protocol v5.1 for kernel f4d1cc31-78f0-4200-9439-2f0bba6365b5
[I 20:01:27.895 LabApp] Saving file at /181012_aaron_helper.ipynb
[W 20:01:27.897 LabApp] Notebook 181012_aaron_helper.ipynb is not trusted
[I 20:01:31.098 LabApp] Copying 181012_aaron_helper.ipynb to /
[W 20:01:31.289 LabApp] Notebook 181012_aaron_helper.ipynb is not trusted
[W 20:01:31.417 LabApp] Notebook 181012_aaron_helper-Copy1.ipynb is not trusted
[W 20:01:35.291 LabApp] Notebook 181012_aaron_helper-Copy1.ipynb is not trusted
[I 20:01:39.995 LabApp] Kernel started: ddfb142f-ba85-4e3d-ad74-1646d41b00e4
[I 20:01:40.314 LabApp] Adapting to protocol v5.1 for kernel ddfb142f-ba85-4e3d-ad74-1646d41b00e4
[I 20:30:40.197 LabApp] Saving file at /181012_granger_viz.ipynb
[I 20:59:29.752 LabApp] Saving file at /181012_granger_viz.ipynb
[I 20:59:31.392 LabApp] Starting buffering for ddfb142f-ba85-4e3d-ad74-1646d41b00e4:e22b89aeb2c9dc4813fca6373b5c3299
[I 20:59:32.205 LabApp] Kernel restarted: ddfb142f-ba85-4e3d-ad74-1646d41b00e4
[I 20:59:35.667 LabApp] Adapting to protocol v5.1 for kernel ddfb142f-ba85-4e3d-ad74-1646d41b00e4
[I 20:59:35.668 LabApp] Restoring connection for ddfb142f-ba85-4e3d-ad74-1646d41b00e4:e22b89aeb2c9dc4813fca6373b5c3299
[I 20:59:35.668 LabApp] Replaying 6 buffered messages
[I 21:01:24.714 LabApp] Saving file at /181012_granger_viz.ipynb
[I 21:01:34.714 LabApp] Saving file at /181012_aaron_helper.ipynb
[W 21:01:34.715 LabApp] Notebook 181012_aaron_helper.ipynb is not trusted
[I 21:22:02.909 LabApp] Starting buffering for ddfb142f-ba85-4e3d-ad74-1646d41b00e4:e22b89aeb2c9dc4813fca6373b5c3299
[I 21:22:03.421 LabApp] Kernel restarted: ddfb142f-ba85-4e3d-ad74-1646d41b00e4
[I 21:22:03.875 LabApp] Adapting to protocol v5.1 for kernel ddfb142f-ba85-4e3d-ad74-1646d41b00e4
[I 21:22:03.876 LabApp] Restoring connection for ddfb142f-ba85-4e3d-ad74-1646d41b00e4:e22b89aeb2c9dc4813fca6373b5c3299
[I 21:22:03.876 LabApp] Replaying 6 buffered messages
[I 21:23:17.110 LabApp] Saving file at /181012_granger_viz.ipynb
[I 21:30:43.667 LabApp] Saving file at /181012_granger_viz.ipynb
[I 21:30:46.893 LabApp] Kernel interrupted: ddfb142f-ba85-4e3d-ad74-1646d41b00e4
[I 21:30:46.895 LabApp] Kernel interrupted: ddfb142f-ba85-4e3d-ad74-1646d41b00e4
[I 21:41:25.639 LabApp] Starting buffering for ddfb142f-ba85-4e3d-ad74-1646d41b00e4:e22b89aeb2c9dc4813fca6373b5c3299
[I 21:41:27.252 LabApp] Kernel restarted: ddfb142f-ba85-4e3d-ad74-1646d41b00e4
[I 21:41:27.781 LabApp] Adapting to protocol v5.1 for kernel ddfb142f-ba85-4e3d-ad74-1646d41b00e4
[I 21:41:27.782 LabApp] Restoring connection for ddfb142f-ba85-4e3d-ad74-1646d41b00e4:e22b89aeb2c9dc4813fca6373b5c3299
[I 21:41:27.782 LabApp] Replaying 5 buffered messages
[I 21:42:07.881 LabApp] Saving file at /181012_granger_viz.ipynb
[I 21:49:07.371 LabApp] Saving file at /181012_granger_viz.ipynb
[I 21:50:20.654 LabApp] Starting buffering for ddfb142f-ba85-4e3d-ad74-1646d41b00e4:e22b89aeb2c9dc4813fca6373b5c3299
[I 21:50:21.169 LabApp] Kernel restarted: ddfb142f-ba85-4e3d-ad74-1646d41b00e4
[I 21:50:21.625 LabApp] Adapting to protocol v5.1 for kernel ddfb142f-ba85-4e3d-ad74-1646d41b00e4
[I 21:50:21.626 LabApp] Restoring connection for ddfb142f-ba85-4e3d-ad74-1646d41b00e4:e22b89aeb2c9dc4813fca6373b5c3299
[I 21:50:21.626 LabApp] Replaying 4 buffered messages
[I 21:51:23.199 LabApp] Saving file at /181012_granger_viz.ipynb
[E 21:53:57.824 LabApp] Couldn't get environment variables for commands: ['source', 'activate', '/home/ubuntu/anaconda3/envs/tensorflow_p27']
    Traceback (most recent call last):
      File "/home/ubuntu/anaconda3/lib/python3.6/site-packages/environment_kernels/activate_helper.py", line 61, in source_env_vars_from_command
        return source_bash(args)
      File "/home/ubuntu/anaconda3/lib/python3.6/site-packages/environment_kernels/activate_helper.py", line 73, in source_bash
        return source_foreign(new_args, stdin=stdin)
      File "/home/ubuntu/anaconda3/lib/python3.6/site-packages/environment_kernels/activate_helper.py", line 191, in source_foreign
        seterrpostcmd=ns.seterrpostcmd)
      File "/home/ubuntu/anaconda3/lib/python3.6/site-packages/environment_kernels/activate_helper.py", line 433, in foreign_shell_data
        universal_newlines=True)
      File "/home/ubuntu/anaconda3/lib/python3.6/subprocess.py", line 336, in check_output
        **kwargs).stdout
      File "/home/ubuntu/anaconda3/lib/python3.6/subprocess.py", line 418, in run
        output=stdout, stderr=stderr)
    subprocess.CalledProcessError: Command '['bash', '-i', '-c', 'set -e\nsource activate /home/ubuntu/anaconda3/envs/tensorflow_p27\necho __XONSH_ENV_BEG__\nenv\necho __XONSH_ENV_END__']' returned non-zero exit status 1.
    
    During handling of the above exception, another exception occurred:
    
    Traceback (most recent call last):
      File "/home/ubuntu/anaconda3/lib/python3.6/site-packages/environment_kernels/envs_conda.py", line 52, in _get_env_vars_for_conda_env
        envs = source_env_vars_from_command(args)
      File "/home/ubuntu/anaconda3/lib/python3.6/site-packages/environment_kernels/activate_helper.py", line 63, in source_env_vars_from_command
        return source_zsh(args)
      File "/home/ubuntu/anaconda3/lib/python3.6/site-packages/environment_kernels/activate_helper.py", line 82, in source_zsh
        return source_foreign(new_args, stdin=stdin)
      File "/home/ubuntu/anaconda3/lib/python3.6/site-packages/environment_kernels/activate_helper.py", line 191, in source_foreign
        seterrpostcmd=ns.seterrpostcmd)
      File "/home/ubuntu/anaconda3/lib/python3.6/site-packages/environment_kernels/activate_helper.py", line 433, in foreign_shell_data
        universal_newlines=True)
      File "/home/ubuntu/anaconda3/lib/python3.6/subprocess.py", line 336, in check_output
        **kwargs).stdout
      File "/home/ubuntu/anaconda3/lib/python3.6/subprocess.py", line 418, in run
        output=stdout, stderr=stderr)
    subprocess.CalledProcessError: Command '['zsh', '-i', '-c', 'set -e\nsource activate /home/ubuntu/anaconda3/envs/tensorflow_p27\necho __XONSH_ENV_BEG__\nenv\necho __XONSH_ENV_END__']' returned non-zero exit status 127.
[I 21:53:57.832 LabApp] Kernel started: ffa3f591-a6bf-44b8-a59f-653c6d4ddf88
[I 21:54:01.474 LabApp] Adapting to protocol v5.1 for kernel ffa3f591-a6bf-44b8-a59f-653c6d4ddf88
[I 21:54:09.062 LabApp] Kernel started: 3c313625-56f9-4377-89db-e0ea9ab4c0fe
[I 21:54:09.383 LabApp] Adapting to protocol v5.1 for kernel 3c313625-56f9-4377-89db-e0ea9ab4c0fe
[I 21:54:27.131 LabApp] Kernel started: ed4a1162-6a5e-427b-b549-10bd96898170
[I 21:54:27.144 LabApp] Kernel started: 18810edb-4093-4c06-81ec-89726e83ac35
[I 21:54:27.604 LabApp] Adapting to protocol v5.1 for kernel ed4a1162-6a5e-427b-b549-10bd96898170
[I 21:54:27.752 LabApp] Adapting to protocol v5.1 for kernel 18810edb-4093-4c06-81ec-89726e83ac35
[W 21:54:44.452 LabApp] Notebook 181012_aaron_helper.ipynb is not trusted
[I 21:54:49.352 LabApp] Adapting to protocol v5.1 for kernel bb9af98f-38e7-4c15-a41c-7b5142d7fefa
[I 22:01:30.487 LabApp] Saving file at /181012_connectivity_viz.ipynb
[I 22:03:23.384 LabApp] Saving file at /181012_connectivity_viz.ipynb
[I 22:24:01.935 LabApp] Kernel started: 8e43c9e9-d4d5-4a20-b63d-7047ba037b4a
[I 22:24:02.260 LabApp] Adapting to protocol v5.1 for kernel 8e43c9e9-d4d5-4a20-b63d-7047ba037b4a
[I 22:24:02.391 LabApp] Adapting to protocol v5.1 for kernel 8e43c9e9-d4d5-4a20-b63d-7047ba037b4a
[W 22:24:05.601 LabApp] Notebook viz_models.ipynb is not trusted
[I 22:24:07.490 LabApp] Kernel started: b9836168-f62f-484c-abdf-fa524b237cb2
[I 22:24:07.891 LabApp] Adapting to protocol v5.1 for kernel b9836168-f62f-484c-abdf-fa524b237cb2
[I 22:24:13.619 LabApp] Kernel started: f6a3c978-bb96-464e-85a8-eff7915f3339
[I 22:24:13.955 LabApp] Adapting to protocol v5.1 for kernel f6a3c978-bb96-464e-85a8-eff7915f3339
[I 22:35:09.653 LabApp] Saving file at /181012_connectivity_viz.ipynb
[I 22:35:10.540 LabApp] Saving file at /181012_connectivity_viz.ipynb
[I 23:01:47.406 LabApp] Saving file at /181012_connectivity_viz.ipynb
[I 23:01:48.929 LabApp] Starting buffering for ddfb142f-ba85-4e3d-ad74-1646d41b00e4:e22b89aeb2c9dc4813fca6373b5c3299
[I 23:01:49.540 LabApp] Kernel restarted: ddfb142f-ba85-4e3d-ad74-1646d41b00e4
[I 23:01:50.100 LabApp] Adapting to protocol v5.1 for kernel ddfb142f-ba85-4e3d-ad74-1646d41b00e4
[I 23:01:50.101 LabApp] Restoring connection for ddfb142f-ba85-4e3d-ad74-1646d41b00e4:e22b89aeb2c9dc4813fca6373b5c3299
[I 23:01:50.101 LabApp] Replaying 3 buffered messages
[I 23:01:54.834 LabApp] Saving file at /181012_connectivity_viz.ipynb
[I 23:06:36.126 LabApp] Saving file at /181012_connectivity_viz.ipynb
[I 23:06:37.474 LabApp] Starting buffering for ddfb142f-ba85-4e3d-ad74-1646d41b00e4:e22b89aeb2c9dc4813fca6373b5c3299
[I 23:06:38.084 LabApp] Kernel restarted: ddfb142f-ba85-4e3d-ad74-1646d41b00e4
[I 23:06:38.571 LabApp] Adapting to protocol v5.1 for kernel ddfb142f-ba85-4e3d-ad74-1646d41b00e4
[I 23:06:38.572 LabApp] Restoring connection for ddfb142f-ba85-4e3d-ad74-1646d41b00e4:e22b89aeb2c9dc4813fca6373b5c3299
[I 23:06:38.572 LabApp] Replaying 3 buffered messages
[I 23:06:46.943 LabApp] Saving file at /181012_connectivity_viz.ipynb
[I 23:08:47.334 LabApp] Saving file at /181012_connectivity_viz.ipynb
[I 23:10:57.024 LabApp] Saving file at /181012_connectivity_viz.ipynb
[I 23:11:04.393 LabApp] Saving file at /181012_connectivity_viz.ipynb
[I 23:11:34.409 LabApp] Saving file at /181012_connectivity_viz.ipynb
[I 23:14:46.928 LabApp] Copying 181012_connectivity_viz.ipynb to /
[I 23:45:14.925 LabApp] Saving file at /181012_connectivity_viz.ipynb
[I 23:45:23.486 LabApp] Starting buffering for ddfb142f-ba85-4e3d-ad74-1646d41b00e4:e22b89aeb2c9dc4813fca6373b5c3299
[I 23:45:26.102 LabApp] Kernel restarted: ddfb142f-ba85-4e3d-ad74-1646d41b00e4
[I 23:45:30.059 LabApp] Adapting to protocol v5.1 for kernel ddfb142f-ba85-4e3d-ad74-1646d41b00e4
[I 23:45:30.062 LabApp] Restoring connection for ddfb142f-ba85-4e3d-ad74-1646d41b00e4:e22b89aeb2c9dc4813fca6373b5c3299
[I 23:45:30.062 LabApp] Replaying 6 buffered messages
[I 23:45:35.823 LabApp] Kernel interrupted: ddfb142f-ba85-4e3d-ad74-1646d41b00e4
[I 23:45:36.522 LabApp] Starting buffering for ddfb142f-ba85-4e3d-ad74-1646d41b00e4:e22b89aeb2c9dc4813fca6373b5c3299
[I 23:45:36.832 LabApp] Kernel restarted: ddfb142f-ba85-4e3d-ad74-1646d41b00e4
[I 23:45:37.286 LabApp] Adapting to protocol v5.1 for kernel ddfb142f-ba85-4e3d-ad74-1646d41b00e4
[I 23:45:37.286 LabApp] Restoring connection for ddfb142f-ba85-4e3d-ad74-1646d41b00e4:e22b89aeb2c9dc4813fca6373b5c3299
[I 23:45:37.286 LabApp] Replaying 3 buffered messages
[I 23:47:49.663 LabApp] Saving file at /181012_connectivity_viz.ipynb
[I 23:47:53.987 LabApp] Starting buffering for ddfb142f-ba85-4e3d-ad74-1646d41b00e4:e22b89aeb2c9dc4813fca6373b5c3299
[I 23:47:54.198 LabApp] Kernel restarted: ddfb142f-ba85-4e3d-ad74-1646d41b00e4
[I 23:47:54.675 LabApp] Adapting to protocol v5.1 for kernel ddfb142f-ba85-4e3d-ad74-1646d41b00e4
[I 23:47:54.676 LabApp] Restoring connection for ddfb142f-ba85-4e3d-ad74-1646d41b00e4:e22b89aeb2c9dc4813fca6373b5c3299
[I 23:47:54.676 LabApp] Replaying 6 buffered messages
[I 23:47:58.378 LabApp] Saving file at /181012_connectivity_viz.ipynb
[I 23:51:40.539 LabApp] Starting buffering for ddfb142f-ba85-4e3d-ad74-1646d41b00e4:e22b89aeb2c9dc4813fca6373b5c3299
[I 23:51:41.050 LabApp] Kernel restarted: ddfb142f-ba85-4e3d-ad74-1646d41b00e4
[I 23:51:41.544 LabApp] Adapting to protocol v5.1 for kernel ddfb142f-ba85-4e3d-ad74-1646d41b00e4
[I 23:51:41.544 LabApp] Restoring connection for ddfb142f-ba85-4e3d-ad74-1646d41b00e4:e22b89aeb2c9dc4813fca6373b5c3299
[I 23:51:41.545 LabApp] Replaying 3 buffered messages
[I 23:51:45.994 LabApp] Saving file at /181012_connectivity_viz.ipynb
[I 23:55:08.003 LabApp] Saving file at /181012_connectivity_viz.ipynb
[I 23:55:11.385 LabApp] Copying 181012_connectivity_viz.ipynb to /
[I 01:56:55.517 LabApp] Saving file at /181012_connectivity_viz.ipynb
[I 02:09:32.105 LabApp] Saving file at /181012_connectivity_viz.ipynb
[I 02:12:54.335 LabApp] Starting buffering for ddfb142f-ba85-4e3d-ad74-1646d41b00e4:e22b89aeb2c9dc4813fca6373b5c3299
[I 02:12:58.956 LabApp] Kernel restarted: ddfb142f-ba85-4e3d-ad74-1646d41b00e4
[I 02:12:59.808 LabApp] Adapting to protocol v5.1 for kernel ddfb142f-ba85-4e3d-ad74-1646d41b00e4
[I 02:12:59.809 LabApp] Restoring connection for ddfb142f-ba85-4e3d-ad74-1646d41b00e4:e22b89aeb2c9dc4813fca6373b5c3299
[I 02:12:59.809 LabApp] Replaying 6 buffered messages
[I 02:13:14.840 LabApp] Saving file at /181012_connectivity_viz.ipynb
[I 05:32:51.758 LabApp] Saving file at /181012_connectivity_viz.ipynb
[I 05:32:55.665 LabApp] Starting buffering for 3f87dee7-d886-49c8-b570-eaa8a118fe83:645cad3a6aa4ef9ad44071937204d703
[I 05:32:55.666 LabApp] Starting buffering for f4d1cc31-78f0-4200-9439-2f0bba6365b5:74ed499bfa8772e3afc3490579e2d225
[I 05:32:55.666 LabApp] Starting buffering for ffa3f591-a6bf-44b8-a59f-653c6d4ddf88:f6231403034e1825a60603180f3ffe92
[I 05:32:55.666 LabApp] Starting buffering for ddfb142f-ba85-4e3d-ad74-1646d41b00e4:e22b89aeb2c9dc4813fca6373b5c3299
[I 05:32:55.666 LabApp] Starting buffering for 3c313625-56f9-4377-89db-e0ea9ab4c0fe:f7aaa280d95475d47c4195d6f211ccaf
[I 05:32:55.667 LabApp] Starting buffering for 18810edb-4093-4c06-81ec-89726e83ac35:2ec7bab241fb98a97cc366711d76eacf
[I 05:32:55.667 LabApp] Starting buffering for bb9af98f-38e7-4c15-a41c-7b5142d7fefa:11b81a7da1574ca037fe445383f333fe
[I 05:32:55.667 LabApp] Starting buffering for b9836168-f62f-484c-abdf-fa524b237cb2:64d783309e8316dcc202c1ded4c12ea6
[I 05:32:55.667 LabApp] Starting buffering for f6a3c978-bb96-464e-85a8-eff7915f3339:950887e50184b7ff448fe7854824c8ad
[I 05:32:55.667 LabApp] Starting buffering for 8e43c9e9-d4d5-4a20-b63d-7047ba037b4a:03fb8da90608d2a050ae273f17dc9633
[I 05:32:55.667 LabApp] Starting buffering for ed4a1162-6a5e-427b-b549-10bd96898170:3563b1f2107a2bd0c3bc36d438cd5ec2
[I 18:01:54.335 LabApp] 302 GET / (127.0.0.1) 0.64ms
[I 18:01:55.698 LabApp] Adapting to protocol v5.1 for kernel f6a3c978-bb96-464e-85a8-eff7915f3339
[I 18:01:55.956 LabApp] Starting buffering for f6a3c978-bb96-464e-85a8-eff7915f3339:70fae901257344d204163389684b2dd6
[W 18:01:56.909 LabApp] Notebook 181012_aaron_helper.ipynb is not trusted
[I 18:01:57.088 LabApp] Build is up to date
[W 18:01:58.856 LabApp] Notebook viz_models.ipynb is not trusted
[I 18:02:03.040 LabApp] Adapting to protocol v5.1 for kernel 8e43c9e9-d4d5-4a20-b63d-7047ba037b4a
[I 18:02:04.556 LabApp] Adapting to protocol v5.1 for kernel 3c313625-56f9-4377-89db-e0ea9ab4c0fe
[I 18:02:06.202 LabApp] Adapting to protocol v5.1 for kernel ffa3f591-a6bf-44b8-a59f-653c6d4ddf88
[I 18:02:08.137 LabApp] Adapting to protocol v5.1 for kernel b9836168-f62f-484c-abdf-fa524b237cb2
[I 18:02:09.956 LabApp] Adapting to protocol v5.1 for kernel f6a3c978-bb96-464e-85a8-eff7915f3339
[I 18:02:11.045 LabApp] Adapting to protocol v5.1 for kernel ed4a1162-6a5e-427b-b549-10bd96898170
[I 18:02:12.136 LabApp] Adapting to protocol v5.1 for kernel ddfb142f-ba85-4e3d-ad74-1646d41b00e4
[I 18:02:13.228 LabApp] Adapting to protocol v5.1 for kernel bb9af98f-38e7-4c15-a41c-7b5142d7fefa
[I 18:02:16.640 LabApp] Adapting to protocol v5.1 for kernel 18810edb-4093-4c06-81ec-89726e83ac35
[I 18:03:36.804 LabApp] Copying 181012_connectivity_viz.ipynb to /
[E 18:03:55.999 LabApp] Couldn't get environment variables for commands: ['source', 'activate', '/home/ubuntu/anaconda3/envs/tensorflow_p27']
    Traceback (most recent call last):
      File "/home/ubuntu/anaconda3/lib/python3.6/site-packages/environment_kernels/activate_helper.py", line 61, in source_env_vars_from_command
        return source_bash(args)
      File "/home/ubuntu/anaconda3/lib/python3.6/site-packages/environment_kernels/activate_helper.py", line 73, in source_bash
        return source_foreign(new_args, stdin=stdin)
      File "/home/ubuntu/anaconda3/lib/python3.6/site-packages/environment_kernels/activate_helper.py", line 191, in source_foreign
        seterrpostcmd=ns.seterrpostcmd)
      File "/home/ubuntu/anaconda3/lib/python3.6/site-packages/environment_kernels/activate_helper.py", line 433, in foreign_shell_data
        universal_newlines=True)
      File "/home/ubuntu/anaconda3/lib/python3.6/subprocess.py", line 336, in check_output
        **kwargs).stdout
      File "/home/ubuntu/anaconda3/lib/python3.6/subprocess.py", line 418, in run
        output=stdout, stderr=stderr)
    subprocess.CalledProcessError: Command '['bash', '-i', '-c', 'set -e\nsource activate /home/ubuntu/anaconda3/envs/tensorflow_p27\necho __XONSH_ENV_BEG__\nenv\necho __XONSH_ENV_END__']' returned non-zero exit status 1.
    
    During handling of the above exception, another exception occurred:
    
    Traceback (most recent call last):
      File "/home/ubuntu/anaconda3/lib/python3.6/site-packages/environment_kernels/envs_conda.py", line 52, in _get_env_vars_for_conda_env
        envs = source_env_vars_from_command(args)
      File "/home/ubuntu/anaconda3/lib/python3.6/site-packages/environment_kernels/activate_helper.py", line 63, in source_env_vars_from_command
        return source_zsh(args)
      File "/home/ubuntu/anaconda3/lib/python3.6/site-packages/environment_kernels/activate_helper.py", line 82, in source_zsh
        return source_foreign(new_args, stdin=stdin)
      File "/home/ubuntu/anaconda3/lib/python3.6/site-packages/environment_kernels/activate_helper.py", line 191, in source_foreign
        seterrpostcmd=ns.seterrpostcmd)
      File "/home/ubuntu/anaconda3/lib/python3.6/site-packages/environment_kernels/activate_helper.py", line 433, in foreign_shell_data
        universal_newlines=True)
      File "/home/ubuntu/anaconda3/lib/python3.6/subprocess.py", line 336, in check_output
        **kwargs).stdout
      File "/home/ubuntu/anaconda3/lib/python3.6/subprocess.py", line 418, in run
        output=stdout, stderr=stderr)
    subprocess.CalledProcessError: Command '['zsh', '-i', '-c', 'set -e\nsource activate /home/ubuntu/anaconda3/envs/tensorflow_p27\necho __XONSH_ENV_BEG__\nenv\necho __XONSH_ENV_END__']' returned non-zero exit status 127.
[I 18:03:56.008 LabApp] Kernel started: 7781457f-09b9-4801-9e01-6b3b1c6775f2
[I 18:04:00.346 LabApp] Adapting to protocol v5.1 for kernel 7781457f-09b9-4801-9e01-6b3b1c6775f2
[I 18:04:00.509 LabApp] Adapting to protocol v5.1 for kernel 7781457f-09b9-4801-9e01-6b3b1c6775f2
[I 18:04:00.664 LabApp] Adapting to protocol v5.1 for kernel 7781457f-09b9-4801-9e01-6b3b1c6775f2
[I 18:16:54.727 LabApp] Saving file at /181014_kanaka_viz.ipynb
[I 18:16:58.498 LabApp] Kernel interrupted: 7781457f-09b9-4801-9e01-6b3b1c6775f2
[I 18:17:00.154 LabApp] Starting buffering for 7781457f-09b9-4801-9e01-6b3b1c6775f2:8d2ab54d86b7189c9bd2b0b33abf2fac
[I 18:17:05.222 LabApp] Kernel restarted: 7781457f-09b9-4801-9e01-6b3b1c6775f2
[I 18:17:05.699 LabApp] Adapting to protocol v5.1 for kernel 7781457f-09b9-4801-9e01-6b3b1c6775f2
[I 18:17:05.699 LabApp] Restoring connection for 7781457f-09b9-4801-9e01-6b3b1c6775f2:8d2ab54d86b7189c9bd2b0b33abf2fac
[I 18:17:05.699 LabApp] Replaying 8 buffered messages
[I 18:17:05.828 LabApp] Adapting to protocol v5.1 for kernel 7781457f-09b9-4801-9e01-6b3b1c6775f2
[I 18:17:07.844 LabApp] Saving file at /181014_kanaka_viz.ipynb
[I 18:17:10.970 LabApp] Starting buffering for 7781457f-09b9-4801-9e01-6b3b1c6775f2:8d2ab54d86b7189c9bd2b0b33abf2fac
[I 18:17:11.181 LabApp] Kernel restarted: 7781457f-09b9-4801-9e01-6b3b1c6775f2
[I 18:17:11.659 LabApp] Adapting to protocol v5.1 for kernel 7781457f-09b9-4801-9e01-6b3b1c6775f2
[I 18:17:11.659 LabApp] Restoring connection for 7781457f-09b9-4801-9e01-6b3b1c6775f2:8d2ab54d86b7189c9bd2b0b33abf2fac
[I 18:17:11.660 LabApp] Replaying 3 buffered messages
[I 18:17:11.788 LabApp] Adapting to protocol v5.1 for kernel 7781457f-09b9-4801-9e01-6b3b1c6775f2
[I 18:17:47.059 LabApp] Saving file at /181014_kanaka_viz.ipynb
[I 18:30:20.680 LabApp] Kernel interrupted: 7781457f-09b9-4801-9e01-6b3b1c6775f2
[I 18:30:28.107 LabApp] Kernel interrupted: 7781457f-09b9-4801-9e01-6b3b1c6775f2
[I 18:33:40.921 LabApp] Saving file at /181014_kanaka_viz.ipynb
[I 18:43:54.064 LabApp] Kernel interrupted: 7781457f-09b9-4801-9e01-6b3b1c6775f2
ERROR:tornado.general:Uncaught exception in ZMQStream callback
Traceback (most recent call last):
  File "/home/ubuntu/anaconda3/envs/tensorflow_p27/lib/python2.7/site-packages/zmq/eventloop/zmqstream.py", line 432, in _run_callback
    callback(*args, **kwargs)
  File "/home/ubuntu/anaconda3/envs/tensorflow_p27/lib/python2.7/site-packages/tornado/stack_context.py", line 276, in null_wrapper
    return fn(*args, **kwargs)
  File "/home/ubuntu/anaconda3/envs/tensorflow_p27/lib/python2.7/site-packages/ipykernel/kernelbase.py", line 283, in dispatcher
    return self.dispatch_shell(stream, msg)
  File "/home/ubuntu/anaconda3/envs/tensorflow_p27/lib/python2.7/site-packages/ipykernel/kernelbase.py", line 233, in dispatch_shell
    handler(stream, idents, msg)
  File "/home/ubuntu/anaconda3/envs/tensorflow_p27/lib/python2.7/site-packages/ipykernel/kernelbase.py", line 399, in execute_request
    user_expressions, allow_stdin)
  File "/home/ubuntu/anaconda3/envs/tensorflow_p27/lib/python2.7/site-packages/ipykernel/ipkernel.py", line 208, in do_execute
    res = shell.run_cell(code, store_history=store_history, silent=silent)
  File "/home/ubuntu/anaconda3/envs/tensorflow_p27/lib/python2.7/site-packages/ipykernel/zmqshell.py", line 537, in run_cell
    return super(ZMQInteractiveShell, self).run_cell(*args, **kwargs)
  File "/home/ubuntu/anaconda3/envs/tensorflow_p27/lib/python2.7/site-packages/IPython/core/interactiveshell.py", line 2722, in run_cell
    self.events.trigger('post_execute')
  File "/home/ubuntu/anaconda3/envs/tensorflow_p27/lib/python2.7/site-packages/IPython/core/events.py", line 74, in trigger
    func(*args, **kwargs)
  File "/home/ubuntu/anaconda3/envs/tensorflow_p27/lib/python2.7/site-packages/matplotlib/pyplot.py", line 149, in post_execute
    draw_all()
  File "/home/ubuntu/anaconda3/envs/tensorflow_p27/lib/python2.7/site-packages/matplotlib/_pylab_helpers.py", line 136, in draw_all
    f_mgr.canvas.draw_idle()
  File "/home/ubuntu/anaconda3/envs/tensorflow_p27/lib/python2.7/site-packages/matplotlib/backend_bases.py", line 2055, in draw_idle
    self.draw(*args, **kwargs)
  File "/home/ubuntu/anaconda3/envs/tensorflow_p27/lib/python2.7/site-packages/matplotlib/backends/backend_agg.py", line 433, in draw
    self.figure.draw(self.renderer)
  File "/home/ubuntu/anaconda3/envs/tensorflow_p27/lib/python2.7/site-packages/matplotlib/artist.py", line 55, in draw_wrapper
    return draw(artist, renderer, *args, **kwargs)
  File "/home/ubuntu/anaconda3/envs/tensorflow_p27/lib/python2.7/site-packages/matplotlib/figure.py", line 1475, in draw
    renderer, self, artists, self.suppressComposite)
  File "/home/ubuntu/anaconda3/envs/tensorflow_p27/lib/python2.7/site-packages/matplotlib/image.py", line 141, in _draw_list_compositing_images
    a.draw(renderer)
  File "/home/ubuntu/anaconda3/envs/tensorflow_p27/lib/python2.7/site-packages/matplotlib/artist.py", line 55, in draw_wrapper
    return draw(artist, renderer, *args, **kwargs)
  File "/home/ubuntu/anaconda3/envs/tensorflow_p27/lib/python2.7/site-packages/matplotlib/axes/_base.py", line 2607, in draw
    mimage._draw_list_compositing_images(renderer, self, artists)
  File "/home/ubuntu/anaconda3/envs/tensorflow_p27/lib/python2.7/site-packages/matplotlib/image.py", line 141, in _draw_list_compositing_images
    a.draw(renderer)
  File "/home/ubuntu/anaconda3/envs/tensorflow_p27/lib/python2.7/site-packages/matplotlib/artist.py", line 55, in draw_wrapper
    return draw(artist, renderer, *args, **kwargs)
  File "/home/ubuntu/anaconda3/envs/tensorflow_p27/lib/python2.7/site-packages/matplotlib/lines.py", line 781, in draw
    renderer.draw_path(gc, tpath, affine.frozen())
  File "/home/ubuntu/anaconda3/envs/tensorflow_p27/lib/python2.7/site-packages/matplotlib/backends/backend_agg.py", line 171, in draw_path
    self._renderer.draw_path(gc, path, transform, rgbFace)
KeyboardInterrupt
[I 18:43:56.182 LabApp] KernelRestarter: restarting kernel (1/5), keep random ports
kernel 7781457f-09b9-4801-9e01-6b3b1c6775f2 restarted
kernel 7781457f-09b9-4801-9e01-6b3b1c6775f2 restarted
[I 18:44:12.912 LabApp] Saving file at /181014_kanaka_viz.ipynb
[I 18:44:16.519 LabApp] Starting buffering for 7781457f-09b9-4801-9e01-6b3b1c6775f2:8ae4743728f3ef33303ced58fcff19f1
[I 18:44:16.728 LabApp] Kernel restarted: 7781457f-09b9-4801-9e01-6b3b1c6775f2
[I 18:44:17.185 LabApp] Adapting to protocol v5.1 for kernel 7781457f-09b9-4801-9e01-6b3b1c6775f2
[I 18:44:17.186 LabApp] Discarding 3 buffered messages for 7781457f-09b9-4801-9e01-6b3b1c6775f2:8ae4743728f3ef33303ced58fcff19f1
[I 18:44:17.314 LabApp] Adapting to protocol v5.1 for kernel 7781457f-09b9-4801-9e01-6b3b1c6775f2
[I 18:44:29.723 LabApp] Saving file at /181014_kanaka_viz.ipynb
[I 18:47:35.891 LabApp] Kernel interrupted: 7781457f-09b9-4801-9e01-6b3b1c6775f2
[I 18:48:06.762 LabApp] Kernel interrupted: 7781457f-09b9-4801-9e01-6b3b1c6775f2
ERROR:tornado.general:Uncaught exception in ZMQStream callback
Traceback (most recent call last):
  File "/home/ubuntu/anaconda3/envs/tensorflow_p27/lib/python2.7/site-packages/zmq/eventloop/zmqstream.py", line 432, in _run_callback
    callback(*args, **kwargs)
  File "/home/ubuntu/anaconda3/envs/tensorflow_p27/lib/python2.7/site-packages/tornado/stack_context.py", line 276, in null_wrapper
    return fn(*args, **kwargs)
  File "/home/ubuntu/anaconda3/envs/tensorflow_p27/lib/python2.7/site-packages/ipykernel/kernelbase.py", line 283, in dispatcher
    return self.dispatch_shell(stream, msg)
  File "/home/ubuntu/anaconda3/envs/tensorflow_p27/lib/python2.7/site-packages/ipykernel/kernelbase.py", line 233, in dispatch_shell
    handler(stream, idents, msg)
  File "/home/ubuntu/anaconda3/envs/tensorflow_p27/lib/python2.7/site-packages/ipykernel/kernelbase.py", line 399, in execute_request
    user_expressions, allow_stdin)
  File "/home/ubuntu/anaconda3/envs/tensorflow_p27/lib/python2.7/site-packages/ipykernel/ipkernel.py", line 208, in do_execute
    res = shell.run_cell(code, store_history=store_history, silent=silent)
  File "/home/ubuntu/anaconda3/envs/tensorflow_p27/lib/python2.7/site-packages/ipykernel/zmqshell.py", line 537, in run_cell
    return super(ZMQInteractiveShell, self).run_cell(*args, **kwargs)
  File "/home/ubuntu/anaconda3/envs/tensorflow_p27/lib/python2.7/site-packages/IPython/core/interactiveshell.py", line 2722, in run_cell
    self.events.trigger('post_execute')
  File "/home/ubuntu/anaconda3/envs/tensorflow_p27/lib/python2.7/site-packages/IPython/core/events.py", line 74, in trigger
    func(*args, **kwargs)
  File "/home/ubuntu/anaconda3/envs/tensorflow_p27/lib/python2.7/site-packages/matplotlib/pyplot.py", line 149, in post_execute
    draw_all()
  File "/home/ubuntu/anaconda3/envs/tensorflow_p27/lib/python2.7/site-packages/matplotlib/_pylab_helpers.py", line 136, in draw_all
    f_mgr.canvas.draw_idle()
  File "/home/ubuntu/anaconda3/envs/tensorflow_p27/lib/python2.7/site-packages/matplotlib/backend_bases.py", line 2055, in draw_idle
    self.draw(*args, **kwargs)
  File "/home/ubuntu/anaconda3/envs/tensorflow_p27/lib/python2.7/site-packages/matplotlib/backends/backend_agg.py", line 433, in draw
    self.figure.draw(self.renderer)
  File "/home/ubuntu/anaconda3/envs/tensorflow_p27/lib/python2.7/site-packages/matplotlib/artist.py", line 55, in draw_wrapper
    return draw(artist, renderer, *args, **kwargs)
  File "/home/ubuntu/anaconda3/envs/tensorflow_p27/lib/python2.7/site-packages/matplotlib/figure.py", line 1475, in draw
    renderer, self, artists, self.suppressComposite)
  File "/home/ubuntu/anaconda3/envs/tensorflow_p27/lib/python2.7/site-packages/matplotlib/image.py", line 141, in _draw_list_compositing_images
    a.draw(renderer)
  File "/home/ubuntu/anaconda3/envs/tensorflow_p27/lib/python2.7/site-packages/matplotlib/artist.py", line 55, in draw_wrapper
    return draw(artist, renderer, *args, **kwargs)
  File "/home/ubuntu/anaconda3/envs/tensorflow_p27/lib/python2.7/site-packages/matplotlib/axes/_base.py", line 2607, in draw
    mimage._draw_list_compositing_images(renderer, self, artists)
  File "/home/ubuntu/anaconda3/envs/tensorflow_p27/lib/python2.7/site-packages/matplotlib/image.py", line 141, in _draw_list_compositing_images
    a.draw(renderer)
  File "/home/ubuntu/anaconda3/envs/tensorflow_p27/lib/python2.7/site-packages/matplotlib/artist.py", line 55, in draw_wrapper
    return draw(artist, renderer, *args, **kwargs)
  File "/home/ubuntu/anaconda3/envs/tensorflow_p27/lib/python2.7/site-packages/matplotlib/lines.py", line 781, in draw
    renderer.draw_path(gc, tpath, affine.frozen())
  File "/home/ubuntu/anaconda3/envs/tensorflow_p27/lib/python2.7/site-packages/matplotlib/backends/backend_agg.py", line 171, in draw_path
    self._renderer.draw_path(gc, path, transform, rgbFace)
KeyboardInterrupt
[I 18:48:10.728 LabApp] KernelRestarter: restarting kernel (1/5), keep random ports
kernel 7781457f-09b9-4801-9e01-6b3b1c6775f2 restarted
kernel 7781457f-09b9-4801-9e01-6b3b1c6775f2 restarted
[I 18:48:18.389 LabApp] Starting buffering for 7781457f-09b9-4801-9e01-6b3b1c6775f2:8d2ab54d86b7189c9bd2b0b33abf2fac
[I 18:48:18.598 LabApp] Kernel restarted: 7781457f-09b9-4801-9e01-6b3b1c6775f2
[I 18:48:19.054 LabApp] Adapting to protocol v5.1 for kernel 7781457f-09b9-4801-9e01-6b3b1c6775f2
[I 18:48:19.055 LabApp] Restoring connection for 7781457f-09b9-4801-9e01-6b3b1c6775f2:8d2ab54d86b7189c9bd2b0b33abf2fac
[I 18:48:19.055 LabApp] Replaying 3 buffered messages
[I 18:48:19.182 LabApp] Adapting to protocol v5.1 for kernel 7781457f-09b9-4801-9e01-6b3b1c6775f2
[I 18:56:44.790 LabApp] Adapting to protocol v5.1 for kernel f6a3c978-bb96-464e-85a8-eff7915f3339
[I 19:13:04.251 LabApp] Kernel interrupted: 7781457f-09b9-4801-9e01-6b3b1c6775f2
[I 19:13:10.939 LabApp] Saving file at /180927_granger-f-test.ipynb
[I 19:13:11.746 LabApp] Saving file at /180927_granger-f-test.ipynb
[I 19:13:26.184 LabApp] Kernel interrupted: 7781457f-09b9-4801-9e01-6b3b1c6775f2
[I 19:13:41.954 LabApp] Kernel interrupted: 7781457f-09b9-4801-9e01-6b3b1c6775f2
[I 19:14:29.572 LabApp] Starting buffering for 7781457f-09b9-4801-9e01-6b3b1c6775f2:8ae4743728f3ef33303ced58fcff19f1
[I 19:14:34.822 LabApp] Kernel restarted: 7781457f-09b9-4801-9e01-6b3b1c6775f2
[I 19:14:35.433 LabApp] Adapting to protocol v5.1 for kernel 7781457f-09b9-4801-9e01-6b3b1c6775f2
[I 19:14:35.433 LabApp] Discarding 3 buffered messages for 7781457f-09b9-4801-9e01-6b3b1c6775f2:8ae4743728f3ef33303ced58fcff19f1
[I 19:14:35.561 LabApp] Adapting to protocol v5.1 for kernel 7781457f-09b9-4801-9e01-6b3b1c6775f2
[I 19:19:13.267 LabApp] Kernel started: f8953729-3771-4b68-bef8-669ab3eb3dcf
[I 19:19:13.874 LabApp] Kernel shutdown: 7781457f-09b9-4801-9e01-6b3b1c6775f2
[I 19:19:14.013 LabApp] Adapting to protocol v5.1 for kernel f8953729-3771-4b68-bef8-669ab3eb3dcf
[I 19:19:14.143 LabApp] Adapting to protocol v5.1 for kernel f8953729-3771-4b68-bef8-669ab3eb3dcf
[I 19:19:17.488 LabApp] Starting buffering for f8953729-3771-4b68-bef8-669ab3eb3dcf:394c9e38ad1a557a69eff72831cc06f0
[I 19:19:17.702 LabApp] Kernel restarted: f8953729-3771-4b68-bef8-669ab3eb3dcf
[I 19:19:18.218 LabApp] Adapting to protocol v5.1 for kernel f8953729-3771-4b68-bef8-669ab3eb3dcf
[I 19:19:18.219 LabApp] Restoring connection for f8953729-3771-4b68-bef8-669ab3eb3dcf:394c9e38ad1a557a69eff72831cc06f0
[I 19:19:18.219 LabApp] Replaying 4 buffered messages
[I 19:19:18.346 LabApp] Adapting to protocol v5.1 for kernel f8953729-3771-4b68-bef8-669ab3eb3dcf
[I 19:27:29.017 LabApp] Saving file at /181014_kanaka_viz.ipynb
[I 21:16:43.240 LabApp] 302 GET / (127.0.0.1) 0.47ms
[I 21:16:44.640 LabApp] Adapting to protocol v5.1 for kernel f8953729-3771-4b68-bef8-669ab3eb3dcf
[I 21:16:45.485 LabApp] Build is up to date
[I 21:16:47.468 LabApp] Adapting to protocol v5.1 for kernel f6a3c978-bb96-464e-85a8-eff7915f3339
[I 21:16:49.953 LabApp] Adapting to protocol v5.1 for kernel ddfb142f-ba85-4e3d-ad74-1646d41b00e4
[I 21:16:54.197 LabApp] Adapting to protocol v5.1 for kernel f8953729-3771-4b68-bef8-669ab3eb3dcf
[I 21:17:35.264 LabApp] Starting buffering for 18810edb-4093-4c06-81ec-89726e83ac35:44d6e32028f27cfb4b4f9f2f334fd6d2
[I 21:17:35.264 LabApp] Starting buffering for bb9af98f-38e7-4c15-a41c-7b5142d7fefa:1fa138a496d976913c6fba530fad47c1
[I 21:17:35.265 LabApp] Starting buffering for ddfb142f-ba85-4e3d-ad74-1646d41b00e4:c2b46c258f9334d9ce0995d5cec5435a
[I 21:17:35.265 LabApp] Starting buffering for ed4a1162-6a5e-427b-b549-10bd96898170:221caa9e8b77ad04eae1d1c1128405ff
[I 21:17:35.265 LabApp] Starting buffering for b9836168-f62f-484c-abdf-fa524b237cb2:41aa0199d9cd0e0fd87242ff36e49551
[I 21:17:35.265 LabApp] Starting buffering for ffa3f591-a6bf-44b8-a59f-653c6d4ddf88:969b0b8ebb9302299f12d66c679ad32b
[I 21:17:35.266 LabApp] Starting buffering for 3c313625-56f9-4377-89db-e0ea9ab4c0fe:706609b508de079dc0585f0b6aa7cdfd
[I 21:17:35.266 LabApp] Starting buffering for 8e43c9e9-d4d5-4a20-b63d-7047ba037b4a:5fcaa5c639dba72d5d4bc74550649a2c
[I 21:17:35.266 LabApp] Starting buffering for f6a3c978-bb96-464e-85a8-eff7915f3339:5f9f3249cf9ef0648c34ec5195820a70
[I 21:17:35.267 LabApp] Starting buffering for f8953729-3771-4b68-bef8-669ab3eb3dcf:394c9e38ad1a557a69eff72831cc06f0
[C 21:17:35.374 LabApp] received signal 15, stopping
[I 21:17:35.376 LabApp] Shutting down 12 kernels
[I 21:17:35.478 LabApp] Kernel shutdown: bb9af98f-38e7-4c15-a41c-7b5142d7fefa
[I 21:17:35.479 LabApp] Kernel shutdown: 3f87dee7-d886-49c8-b570-eaa8a118fe83
[I 21:17:35.479 LabApp] Kernel shutdown: f4d1cc31-78f0-4200-9439-2f0bba6365b5
[I 21:17:36.181 LabApp] Kernel shutdown: ddfb142f-ba85-4e3d-ad74-1646d41b00e4
[I 21:17:36.181 LabApp] Kernel shutdown: ffa3f591-a6bf-44b8-a59f-653c6d4ddf88
[I 21:17:36.181 LabApp] Kernel shutdown: 3c313625-56f9-4377-89db-e0ea9ab4c0fe
[I 21:17:36.181 LabApp] Kernel shutdown: ed4a1162-6a5e-427b-b549-10bd96898170
[I 21:17:36.181 LabApp] Kernel shutdown: 18810edb-4093-4c06-81ec-89726e83ac35
[I 21:17:36.182 LabApp] Kernel shutdown: 8e43c9e9-d4d5-4a20-b63d-7047ba037b4a
[I 21:17:36.182 LabApp] Kernel shutdown: b9836168-f62f-484c-abdf-fa524b237cb2
[I 21:17:36.182 LabApp] Kernel shutdown: f6a3c978-bb96-464e-85a8-eff7915f3339
[I 21:17:36.182 LabApp] Kernel shutdown: f8953729-3771-4b68-bef8-669ab3eb3dcf
